<?xml version="1.0"?>
<robot name="explorover" xmlns:xacro="http://ros.org/wiki/xacro">

  <!-- Base Link (Chassis) -->
  <link name="base_link">
    <visual>
      <geometry>
        <box size="0.17 0.13 0.03"/>
      </geometry>
      <origin xyz="0 0 0.015" rpy="0 0 0"/>
      <material name="clear_plastic">
        <color rgba="0.8 0.8 1.0 0.5"/>
      </material>
    </visual>
    <collision>
      <geometry>
        <box size="0.17 0.13 0.03"/>
      </geometry>
      <origin xyz="0 0 0.015" rpy="0 0 0"/>
    </collision>
    <inertial>
      <mass value="1.0"/> <!-- todo: weigh rover-->
      <origin xyz="0 0 0.015"/>
      <inertia 
        ixx="0.001" ixy="0.0"  ixz="0.0"
        iyy="0.001" iyz="0.0"
        izz="0.001"/>
    </inertial>
  </link>

  <!-- Left Wheel -->
  <link name="left_wheel_link">
    <visual>
      <geometry>
        <cylinder length="0.02" radius="0.0325"/>
      </geometry>
      <origin xyz="0 0 0" rpy="0 0 0"/>
      <material name="black">
        <color rgba="0.2 0.2 0.2 1.0"/>
      </material>
    </visual>
    <collision>
      <geometry>
        <cylinder length="0.02" radius="0.0325"/>
      </geometry>
      <origin xyz="0 0 0"/>
    </collision>
    <inertial>
      <mass value="0.1"/>
      <origin xyz="0 0 0"/>
      <inertia 
        ixx="0.0001" ixy="0.0" ixz="0.0"
        iyy="0.0001" iyz="0.0"
        izz="0.0001"/>
    </inertial>
  </link>

  <!-- Right Wheel -->
  <link name="right_wheel_link">
    <visual>
      <geometry>
        <cylinder length="0.02" radius="0.0325"/>
      </geometry>
      <origin xyz="0 0 0"/>
      <material name="black">
        <color rgba="0.2 0.2 0.2 1.0"/>
      </material>
    </visual>
    <collision>
      <geometry>
        <cylinder length="0.02" radius="0.0325"/>
      </geometry>
      <origin xyz="0 0 0"/>
    </collision>
    <inertial>
      <mass value="0.1"/>
      <origin xyz="0 0 0"/>
      <inertia
        ixx="0.0001" ixy="0.0" ixz="0.0"
        iyy="0.0001" iyz="0.0"
        izz="0.0001"/>
    </inertial>
  </link>

  <!-- Rear Caster -->
  <link name="caster_link">
    <visual>
      <geometry>
        <sphere radius="0.015"/>
      </geometry>
      <origin xyz="0 0 0.015"/>
      <material name="grey">
        <color rgba="0.5 0.5 0.5 1.0"/>
      </material>
    </visual>
    <collision>
      <geometry>
        <sphere radius="0.015"/>
      </geometry>
      <origin xyz="0 0 0.015"/>
    </collision>
    <inertial>
      <mass value="0.05"/>
      <origin xyz="0 0 0.015"/>
      <inertia 
        ixx="0.00005" ixy="0.0" ixz="0.0"
        iyy="0.00005" iyz="0.0"
        izz="0.00005"/>
    </inertial>
  </link>

  <!-- Raspberry Pi Deck -->
  <link name="pi_deck_link">
    <visual>
      <geometry>
        <box size="0.08 0.05 0.01"/>
      </geometry>
      <origin xyz="0.0 0.0 0.06"/>
      <material name="pi_fiberglass">
        <color rgba="0.2 0.8 0.2 1.0"/>
      </material>
    </visual>
    <collision>
      <geometry>
        <box size="0.08 0.05 0.01"/>
      </geometry>
      <origin xyz="0.0 0.0 0.06"/>
    </collision>
    <inertial>
      <mass value="0.2"/>
      <origin xyz="0.0 0.0 0.06"/>
      <inertia
        ixx="0.0002" ixy="0.0" ixz="0.0"
        iyy="0.0002" iyz="0.0"
        izz="0.0002"/>
    </inertial>
  </link>

  <!-- Logitech Camera -->
  <link name="camera_link">
    <visual>
      <geometry>
        <box size="0.05 0.04 0.03"/>
      </geometry>
      <origin xyz="0.08 0.0 0.05"/>
      <material name="black">
        <color rgba="0.1 0.1 0.1 1.0"/>
      </material>
    </visual>
    <collision>
      <geometry>
        <box size="0.05 0.04 0.03"/>
      </geometry>
      <origin xyz="0.08 0.0 0.05"/>
    </collision>
    <inertial>
      <mass value="0.1"/>
      <origin xyz="0.08 0.0 0.05"/>
      <inertia
        ixx="0.0001" ixy="0.0" ixz="0.0"
        iyy="0.0001" iyz="0.0"
        izz="0.0001"/>
    </inertial>
  </link>

  <!-- Joints -->

  <!-- Base to Left Wheel -->
  <joint name="left_wheel_joint" type="continuous">
    <parent link="base_link"/>
    <child link="left_wheel_link"/>
    <!-- Position the left wheel on the left side -->
    <origin xyz="0.0 0.06 0.015" rpy="0 0 0"/>
    <axis xyz="0 1 0"/>
  </joint>

  <!-- Base to Right Wheel -->
  <joint name="right_wheel_joint" type="continuous">
    <parent link="base_link"/>
    <child link="right_wheel_link"/>
    <!-- Position the right wheel on the right side -->
    <origin xyz="0.0 -0.06 0.015" rpy="0 0 0"/>
    <axis xyz="0 1 0"/>
  </joint>

  <!-- Base to Caster -->
  <joint name="caster_joint" type="fixed">
    <parent link="base_link"/>
    <child link="caster_link"/>
    <!-- Place caster near the back center -->
    <origin xyz="-0.07 0.0 0.0" rpy="0 0 0"/>
  </joint>

  <!-- Base to Pi Deck -->
  <joint name="pi_deck_joint" type="fixed">
    <parent link="base_link"/>
    <child link="pi_deck_link"/>
    <origin xyz="0.0 0.0 0.0"/>
  </joint>

  <!-- Base to Camera -->
  <joint name="camera_joint" type="fixed">
    <parent link="base_link"/>
    <child link="camera_link"/>
    <!-- Place the camera near the front, above the base -->
    <origin xyz="0.0 0.0 0.0"/>
  </joint>

</robot>
